benchio.0
=========
  * Error codes = 1
  * 1 exceptions found
    * 1 x FileNotFoundError: [Errno 2] No such file or directory: '/tmp/pytest-of-delaunap/pytest-52/test_milabench_bad_run_before_0/venv/benchio/bin/voir'
        | Traceback (most recent call last):
        |   File "$SRC/milabench/milabench/commands/executors.py", line 35, in execute
        |     return await run(
        |            ^^^^^^^^^^
        |   File "$SRC/milabench/milabench/alt_async.py", line 159, in wrapped
        |     while (x := next(g)) is not None:
        |                 ^^^^^^^
        |   File "$SRC/milabench/milabench/alt_async.py", line 176, in run
        |     mx = voir_run(argv, info=info, **kwargs, timeout=0)
        |          ^^^^^^^^^^^^^^^^^^^^^^^^^^^^^^^^^^^^^^^^^^^^^^
        |   File "$SRC/conda/lib/python3.11/site-packages/voir/proc.py", line 77, in run
        |     mp.start(argv, info=info, env=env, **options)
        |   File "$SRC/conda/lib/python3.11/site-packages/voir/proc.py", line 148, in start
        |     proc = subprocess.Popen(
        |            ^^^^^^^^^^^^^^^^^
        |   File "$SRC/conda/lib/python3.11/subprocess.py", line 1026, in __init__
        |     self._execute_child(args, executable, preexec_fn, close_fds,
        |   File "$SRC/conda/lib/python3.11/subprocess.py", line 1950, in _execute_child
        |     raise child_exception_type(errno_num, err_msg, err_filename)
        | FileNotFoundError: [Errno 2] No such file or directory: '/tmp/pytest-of-delaunap/pytest-52/test_milabench_bad_run_before_0/venv/benchio/bin/voir'
benchio.1
=========
  * Error codes = 1
  * 1 exceptions found
    * 1 x FileNotFoundError: [Errno 2] No such file or directory: '/tmp/pytest-of-delaunap/pytest-52/test_milabench_bad_run_before_0/venv/benchio/bin/voir'
        | Traceback (most recent call last):
        |   File "$SRC/milabench/milabench/commands/executors.py", line 35, in execute
        |     return await run(
        |            ^^^^^^^^^^
        |   File "$SRC/milabench/milabench/alt_async.py", line 159, in wrapped
        |     while (x := next(g)) is not None:
        |                 ^^^^^^^
        |   File "$SRC/milabench/milabench/alt_async.py", line 176, in run
        |     mx = voir_run(argv, info=info, **kwargs, timeout=0)
        |          ^^^^^^^^^^^^^^^^^^^^^^^^^^^^^^^^^^^^^^^^^^^^^^
        |   File "$SRC/conda/lib/python3.11/site-packages/voir/proc.py", line 77, in run
        |     mp.start(argv, info=info, env=env, **options)
        |   File "$SRC/conda/lib/python3.11/site-packages/voir/proc.py", line 148, in start
        |     proc = subprocess.Popen(
        |            ^^^^^^^^^^^^^^^^^
        |   File "$SRC/conda/lib/python3.11/subprocess.py", line 1026, in __init__
        |     self._execute_child(args, executable, preexec_fn, close_fds,
        |   File "$SRC/conda/lib/python3.11/subprocess.py", line 1950, in _execute_child
        |     raise child_exception_type(errno_num, err_msg, err_filename)
        | FileNotFoundError: [Errno 2] No such file or directory: '/tmp/pytest-of-delaunap/pytest-52/test_milabench_bad_run_before_0/venv/benchio/bin/voir'
